[2025-10-06T16:29:33.251+0000] {taskinstance.py:1083} INFO - Dependencies all met for <TaskInstance: kmeans_dag.load_dataset_task manual__2025-10-06T16:29:31.459834+00:00 [queued]>
[2025-10-06T16:29:33.255+0000] {taskinstance.py:1083} INFO - Dependencies all met for <TaskInstance: kmeans_dag.load_dataset_task manual__2025-10-06T16:29:31.459834+00:00 [queued]>
[2025-10-06T16:29:33.255+0000] {taskinstance.py:1279} INFO - 
--------------------------------------------------------------------------------
[2025-10-06T16:29:33.255+0000] {taskinstance.py:1280} INFO - Starting attempt 1 of 2
[2025-10-06T16:29:33.255+0000] {taskinstance.py:1281} INFO - 
--------------------------------------------------------------------------------
[2025-10-06T16:29:33.260+0000] {taskinstance.py:1300} INFO - Executing <Task(PythonOperator): load_dataset_task> on 2025-10-06 16:29:31.459834+00:00
[2025-10-06T16:29:33.263+0000] {standard_task_runner.py:55} INFO - Started process 3881 to run task
[2025-10-06T16:29:33.265+0000] {standard_task_runner.py:82} INFO - Running: ['***', 'tasks', 'run', 'kmeans_dag', 'load_dataset_task', 'manual__2025-10-06T16:29:31.459834+00:00', '--job-id', '7', '--raw', '--subdir', 'DAGS_FOLDER/kmeans_dag.py', '--cfg-path', '/tmp/tmp0yy0i8tc']
[2025-10-06T16:29:33.266+0000] {standard_task_runner.py:83} INFO - Job 7: Subtask load_dataset_task
[2025-10-06T16:29:33.291+0000] {task_command.py:388} INFO - Running <TaskInstance: kmeans_dag.load_dataset_task manual__2025-10-06T16:29:31.459834+00:00 [running]> on host 7ba1f4109bc7
[2025-10-06T16:29:33.319+0000] {taskinstance.py:1509} INFO - Exporting the following env vars:
AIRFLOW_CTX_DAG_OWNER=***
AIRFLOW_CTX_DAG_ID=kmeans_dag
AIRFLOW_CTX_TASK_ID=load_dataset_task
AIRFLOW_CTX_EXECUTION_DATE=2025-10-06T16:29:31.459834+00:00
AIRFLOW_CTX_TRY_NUMBER=1
AIRFLOW_CTX_DAG_RUN_ID=manual__2025-10-06T16:29:31.459834+00:00
[2025-10-06T16:29:33.320+0000] {taskinstance.py:1768} ERROR - Task failed with exception
Traceback (most recent call last):
  File "/home/airflow/.local/lib/python3.7/site-packages/airflow/operators/python.py", line 175, in execute
    return_value = self.execute_callable()
  File "/home/airflow/.local/lib/python3.7/site-packages/airflow/operators/python.py", line 192, in execute_callable
    return self.python_callable(*self.op_args, **self.op_kwargs)
  File "/opt/airflow/dags/kmeans_dag.py", line 29, in task_load_dataset
    df = load_dataset()
NameError: name 'load_dataset' is not defined
[2025-10-06T16:29:33.323+0000] {taskinstance.py:1323} INFO - Marking task as UP_FOR_RETRY. dag_id=kmeans_dag, task_id=load_dataset_task, execution_date=20251006T162931, start_date=20251006T162933, end_date=20251006T162933
[2025-10-06T16:29:33.327+0000] {standard_task_runner.py:105} ERROR - Failed to execute job 7 for task load_dataset_task (name 'load_dataset' is not defined; 3881)
[2025-10-06T16:29:33.369+0000] {local_task_job.py:208} INFO - Task exited with return code 1
[2025-10-06T16:29:33.381+0000] {taskinstance.py:2578} INFO - 0 downstream tasks scheduled from follow-on schedule check
